2024-07-07 07:47:59,389 [DEBUG]: zhowtenko.oleksiy@gmail.com user successfully created
2024-07-07 07:47:59,389 [ERROR]: An unhandled exception occurred
  + Exception Group Traceback (most recent call last):
  |   File "D:\Cor-Pass\.venv\Lib\site-packages\starlette\_utils.py", line 87, in collapse_excgroups
  |     yield
  |   File "D:\Cor-Pass\.venv\Lib\site-packages\starlette\middleware\base.py", line 190, in __call__
  |     async with anyio.create_task_group() as task_group:
  |   File "D:\Cor-Pass\.venv\Lib\site-packages\anyio\_backends\_asyncio.py", line 680, in __aexit__
  |     raise BaseExceptionGroup(
  | ExceptionGroup: unhandled errors in a TaskGroup (1 sub-exception)
  +-+---------------- 1 ----------------
    | Traceback (most recent call last):
    |   File "D:\Cor-Pass\.venv\Lib\site-packages\starlette\middleware\errors.py", line 164, in __call__
    |     await self.app(scope, receive, _send)
    |   File "D:\Cor-Pass\.venv\Lib\site-packages\starlette\middleware\base.py", line 189, in __call__
    |     with collapse_excgroups():
    |   File "C:\Users\Zhowt\AppData\Local\Programs\Python\Python312\Lib\contextlib.py", line 158, in __exit__
    |     self.gen.throw(value)
    |   File "D:\Cor-Pass\.venv\Lib\site-packages\starlette\_utils.py", line 93, in collapse_excgroups
    |     raise exc
    |   File "D:\Cor-Pass\.venv\Lib\site-packages\starlette\middleware\base.py", line 191, in __call__
    |     response = await self.dispatch_func(request, call_next)
    |                ^^^^^^^^^^^^^^^^^^^^^^^^^^^^^^^^^^^^^^^^^^^^
    |   File "D:\Cor-Pass\main.py", line 137, in add_process_time_header
    |     response = await call_next(request)
    |                ^^^^^^^^^^^^^^^^^^^^^^^^
    |   File "D:\Cor-Pass\.venv\Lib\site-packages\starlette\middleware\base.py", line 165, in call_next
    |     raise app_exc
    |   File "D:\Cor-Pass\.venv\Lib\site-packages\starlette\middleware\base.py", line 151, in coro
    |     await self.app(scope, receive_or_disconnect, send_no_error)
    |   File "D:\Cor-Pass\.venv\Lib\site-packages\starlette\middleware\base.py", line 189, in __call__
    |     with collapse_excgroups():
    |   File "C:\Users\Zhowt\AppData\Local\Programs\Python\Python312\Lib\contextlib.py", line 158, in __exit__
    |     self.gen.throw(value)
    |   File "D:\Cor-Pass\.venv\Lib\site-packages\starlette\_utils.py", line 93, in collapse_excgroups
    |     raise exc
    |   File "D:\Cor-Pass\.venv\Lib\site-packages\starlette\middleware\base.py", line 191, in __call__
    |     response = await self.dispatch_func(request, call_next)
    |                ^^^^^^^^^^^^^^^^^^^^^^^^^^^^^^^^^^^^^^^^^^^^
    |   File "D:\Cor-Pass\main.py", line 116, in verify_request_signature
    |     return await call_next(request)
    |            ^^^^^^^^^^^^^^^^^^^^^^^^
    |   File "D:\Cor-Pass\.venv\Lib\site-packages\starlette\middleware\base.py", line 165, in call_next
    |     raise app_exc
    |   File "D:\Cor-Pass\.venv\Lib\site-packages\starlette\middleware\base.py", line 151, in coro
    |     await self.app(scope, receive_or_disconnect, send_no_error)
    |   File "D:\Cor-Pass\.venv\Lib\site-packages\starlette\middleware\cors.py", line 93, in __call__
    |     await self.simple_response(scope, receive, send, request_headers=headers)
    |   File "D:\Cor-Pass\.venv\Lib\site-packages\starlette\middleware\cors.py", line 148, in simple_response
    |     await self.app(scope, receive, send)
    |   File "D:\Cor-Pass\.venv\Lib\site-packages\starlette\middleware\exceptions.py", line 65, in __call__
    |     await wrap_app_handling_exceptions(self.app, conn)(scope, receive, send)
    |   File "D:\Cor-Pass\.venv\Lib\site-packages\starlette\_exception_handler.py", line 64, in wrapped_app
    |     raise exc
    |   File "D:\Cor-Pass\.venv\Lib\site-packages\starlette\_exception_handler.py", line 53, in wrapped_app
    |     await app(scope, receive, sender)
    |   File "D:\Cor-Pass\.venv\Lib\site-packages\starlette\routing.py", line 756, in __call__
    |     await self.middleware_stack(scope, receive, send)
    |   File "D:\Cor-Pass\.venv\Lib\site-packages\starlette\routing.py", line 776, in app
    |     await route.handle(scope, receive, send)
    |   File "D:\Cor-Pass\.venv\Lib\site-packages\starlette\routing.py", line 297, in handle
    |     await self.app(scope, receive, send)
    |   File "D:\Cor-Pass\.venv\Lib\site-packages\starlette\routing.py", line 77, in app
    |     await wrap_app_handling_exceptions(app, request)(scope, receive, send)
    |   File "D:\Cor-Pass\.venv\Lib\site-packages\starlette\_exception_handler.py", line 64, in wrapped_app
    |     raise exc
    |   File "D:\Cor-Pass\.venv\Lib\site-packages\starlette\_exception_handler.py", line 53, in wrapped_app
    |     await app(scope, receive, sender)
    |   File "D:\Cor-Pass\.venv\Lib\site-packages\starlette\routing.py", line 72, in app
    |     response = await func(request)
    |                ^^^^^^^^^^^^^^^^^^^
    |   File "D:\Cor-Pass\.venv\Lib\site-packages\fastapi\routing.py", line 296, in app
    |     content = await serialize_response(
    |               ^^^^^^^^^^^^^^^^^^^^^^^^^
    |   File "D:\Cor-Pass\.venv\Lib\site-packages\fastapi\routing.py", line 155, in serialize_response
    |     raise ResponseValidationError(
    | fastapi.exceptions.ResponseValidationError: 1 validation errors:
    |   {'type': 'missing', 'loc': ('response', 'email'), 'msg': 'Field required', 'input': {'user': <cor_pass.database.models.User object at 0x0000022ED4A02540>, 'detail': 'User successfully created'}}
    | 
    +------------------------------------

During handling of the above exception, another exception occurred:

Traceback (most recent call last):
  File "D:\Cor-Pass\.venv\Lib\site-packages\starlette\middleware\errors.py", line 164, in __call__
    await self.app(scope, receive, _send)
  File "D:\Cor-Pass\.venv\Lib\site-packages\starlette\middleware\base.py", line 189, in __call__
    with collapse_excgroups():
  File "C:\Users\Zhowt\AppData\Local\Programs\Python\Python312\Lib\contextlib.py", line 158, in __exit__
    self.gen.throw(value)
  File "D:\Cor-Pass\.venv\Lib\site-packages\starlette\_utils.py", line 93, in collapse_excgroups
    raise exc
  File "D:\Cor-Pass\.venv\Lib\site-packages\starlette\middleware\base.py", line 191, in __call__
    response = await self.dispatch_func(request, call_next)
               ^^^^^^^^^^^^^^^^^^^^^^^^^^^^^^^^^^^^^^^^^^^^
  File "D:\Cor-Pass\main.py", line 137, in add_process_time_header
    response = await call_next(request)
               ^^^^^^^^^^^^^^^^^^^^^^^^
  File "D:\Cor-Pass\.venv\Lib\site-packages\starlette\middleware\base.py", line 165, in call_next
    raise app_exc
  File "D:\Cor-Pass\.venv\Lib\site-packages\starlette\middleware\base.py", line 151, in coro
    await self.app(scope, receive_or_disconnect, send_no_error)
  File "D:\Cor-Pass\.venv\Lib\site-packages\starlette\middleware\base.py", line 189, in __call__
    with collapse_excgroups():
  File "C:\Users\Zhowt\AppData\Local\Programs\Python\Python312\Lib\contextlib.py", line 158, in __exit__
    self.gen.throw(value)
  File "D:\Cor-Pass\.venv\Lib\site-packages\starlette\_utils.py", line 93, in collapse_excgroups
    raise exc
  File "D:\Cor-Pass\.venv\Lib\site-packages\starlette\middleware\base.py", line 191, in __call__
    response = await self.dispatch_func(request, call_next)
               ^^^^^^^^^^^^^^^^^^^^^^^^^^^^^^^^^^^^^^^^^^^^
  File "D:\Cor-Pass\main.py", line 116, in verify_request_signature
    return await call_next(request)
           ^^^^^^^^^^^^^^^^^^^^^^^^
  File "D:\Cor-Pass\.venv\Lib\site-packages\starlette\middleware\base.py", line 165, in call_next
    raise app_exc
  File "D:\Cor-Pass\.venv\Lib\site-packages\starlette\middleware\base.py", line 151, in coro
    await self.app(scope, receive_or_disconnect, send_no_error)
  File "D:\Cor-Pass\.venv\Lib\site-packages\starlette\middleware\cors.py", line 93, in __call__
    await self.simple_response(scope, receive, send, request_headers=headers)
  File "D:\Cor-Pass\.venv\Lib\site-packages\starlette\middleware\cors.py", line 148, in simple_response
    await self.app(scope, receive, send)
  File "D:\Cor-Pass\.venv\Lib\site-packages\starlette\middleware\exceptions.py", line 65, in __call__
    await wrap_app_handling_exceptions(self.app, conn)(scope, receive, send)
  File "D:\Cor-Pass\.venv\Lib\site-packages\starlette\_exception_handler.py", line 64, in wrapped_app
    raise exc
  File "D:\Cor-Pass\.venv\Lib\site-packages\starlette\_exception_handler.py", line 53, in wrapped_app
    await app(scope, receive, sender)
  File "D:\Cor-Pass\.venv\Lib\site-packages\starlette\routing.py", line 756, in __call__
    await self.middleware_stack(scope, receive, send)
  File "D:\Cor-Pass\.venv\Lib\site-packages\starlette\routing.py", line 776, in app
    await route.handle(scope, receive, send)
  File "D:\Cor-Pass\.venv\Lib\site-packages\starlette\routing.py", line 297, in handle
    await self.app(scope, receive, send)
  File "D:\Cor-Pass\.venv\Lib\site-packages\starlette\routing.py", line 77, in app
    await wrap_app_handling_exceptions(app, request)(scope, receive, send)
  File "D:\Cor-Pass\.venv\Lib\site-packages\starlette\_exception_handler.py", line 64, in wrapped_app
    raise exc
  File "D:\Cor-Pass\.venv\Lib\site-packages\starlette\_exception_handler.py", line 53, in wrapped_app
    await app(scope, receive, sender)
  File "D:\Cor-Pass\.venv\Lib\site-packages\starlette\routing.py", line 72, in app
    response = await func(request)
               ^^^^^^^^^^^^^^^^^^^
  File "D:\Cor-Pass\.venv\Lib\site-packages\fastapi\routing.py", line 296, in app
    content = await serialize_response(
              ^^^^^^^^^^^^^^^^^^^^^^^^^
  File "D:\Cor-Pass\.venv\Lib\site-packages\fastapi\routing.py", line 155, in serialize_response
    raise ResponseValidationError(
fastapi.exceptions.ResponseValidationError: 1 validation errors:
  {'type': 'missing', 'loc': ('response', 'email'), 'msg': 'Field required', 'input': {'user': <cor_pass.database.models.User object at 0x0000022ED4A02540>, 'detail': 'User successfully created'}}

